Workbook

Sheet LEEME
A1: MAESTRO DE PRODUCTOS - PANADERÍA Y PASTELERÍA CON OBRADOR
A3: COMO USAR ESTE LIBRO
A4: 1 | B4: Rellena primero la hoja PROVEEDORES y revisa la hoja CATALOGOS (puedes añadir familias, subfamilias, ubicaciones, etc.).
A5: 2 | B5: Carga los productos en la hoja MAESTRO_PRODUCTOS. Las filas en beige (3 a 35) son EJEMPLOS: bórralas antes de cargar tus datos reales.
A6: 3 | B6: Las columnas con fondo VERDE son fórmulas calculadas: no escribas en ellas. El resto son campos de captura.
A7: 4 | B7: Las celdas con desplegable solo aceptan valores de los catálogos. Si necesitas un valor nuevo, añádelo primero en CATALOGOS.
A8: 5 | B8: Un CODIGO duplicado se marca automáticamente en rojo. El código es la llave del sistema: nunca lo reutilices ni lo cambies una vez emitido.
A9: 7 | B9: Antes de dar de alta cualquier artículo, lee la hoja CODIFICACION: define cómo se forma el código y el procedimiento de alta, modificación y baja.
A10: 8 | B10: El bloque POLITICA DE PRECIO calcula solo si estás vendiendo bien o mal. Los umbrales del semáforo se configuran en la hoja PARAMETROS.
A12: CÓMO FUNCIONA LA POLÍTICA DE PRECIO
A13: Los dos métodos | B13: METODO_PRECIO = MARGEN: tú fijas el margen que quieres y el sistema calcula el precio. METODO_PRECIO = FIJO: tú fijas el precio (porque lo manda el mercado, la competencia o el precio psicológico) y el sistema se limita a auditarlo.
A14: La clave | B14: Rellena SIEMPRE el MARGEN_OBJETIVO_%, incluso cuando el precio sea FIJO. Ese es el caso más valioso: el sistema compara lo que cobras con lo que deberías cobrar y te dice si estás vendiendo bien o mal, en puntos porcentuales y en euros por unidad.
A15: Qué mirar | B15: DIAGNOSTICO_PRECIO da el veredicto en una palabra. DESVIACION_PP dice cuánto te desvías. DIFERENCIA_EUR_UD traduce esa desviación a euros que dejas de ingresar en cada venta: multiplícalo por las unidades que vendes al mes y tendrás el impacto real.
A16: 6 | B16: Hay 500 filas preparadas con fórmulas y validaciones. Si necesitas más, copia la última fila hacia abajo.
A18: CRITERIO CLAVE PARA UN NEGOCIO CON OBRADOR
A19: TIPO_ARTICULO | B19: Es el campo que estructura todo el sistema. Un mismo negocio maneja cinco naturalezas distintas de artículo y cada una se controla diferente:
A20: MP | B20: Materia prima: se compra, se consume en producción, nunca se vende tal cual. Se valora por coste de compra.
A21: IN | B21: Insumo o envase: se compra y se consume, pero no forma parte de la fórmula alimentaria (bolsas, cajas, etiquetas). Se imputa al coste de producto o al gasto.
A22: SE | B22: Semielaborado: se produce internamente y se consume en otra producción (masa madre, crema pastelera, plancha de bizcocho). Es a la vez salida de una orden y entrada de otra. Su coste sale de su propia receta.
A23: PT | B23: Producto terminado: se produce internamente y se vende. Su coste NO se captura, se calcula desde la receta.
A24: RV | B24: Reventa: se compra terminado y se vende sin transformar (bebidas, café en grano). Coste = precio de compra.
A26: ADVERTENCIA SOBRE COSTE_UD_VENTA | B26: Para los artículos PT y SE este campo es provisional: debe alimentarse desde el escandallo (receta) cuando construyamos el módulo de producción. Mientras tanto, cárgalo con tu mejor estimación para poder medir margen desde el primer día, pero no lo tomes como coste real. Todo el diagnóstico de precio depende de él: si el coste es una estimación, el semáforo indica tendencia, no verdad contable.
A27: ADVERTENCIA SOBRE PRECIOS | B27: Todos los precios, costes y plazos de las filas de ejemplo son ILUSTRATIVOS, inventados para mostrar el formato. Sustituyelos por tus datos reales de albaran y de tarifa.
A28: ADVERTENCIA FISCAL | B28: Los códigos de IVA de la hoja TABLA_IVA reflejan la situación general del sector en España, pero la clasificación fiscal de cada referencia debe validarla tu asesor. Ver notas y referencias en esa hoja.
A30: DICCIONARIO DE DATOS - MAESTRO_PRODUCTOS
A31: BLOQUE | B31: CAMPO | C31: OBLIG. | D31: ORIGEN | E31: DESCRIPCION Y CRITERIO DE CARGA
A32: IDENTIFICACION | B32: CODIGO | C32: SI | D32: Captura | E32: Llave única e irrepetible del artículo. Respeta tu codificación actual. Regla de oro: no reutilizar códigos de artículos dados de baja.
A33: IDENTIFICACION | B33: COD_BARRAS_EAN | C33: No | D33: Captura | E33: EAN-13 para lectura en TPV. Solo en artículos etiquetados o de reventa.
A34: IDENTIFICACION | B34: DESCRIPCION_TPV | C34: SI | D34: Captura | E34: Nombre corto (max. 30 caracteres) que se imprime en el ticket y aparece en la pantalla de venta.
A35: IDENTIFICACION | B35: DESCRIPCION_COMPLETA | C35: SI | D35: Captura | E35: Denominación completa y sin ambigüedad, incluyendo formato o gramaje. Es lo que evita duplicados en el maestro.
A36: CLASIFICACION | B36: TIPO_ARTICULO | C36: SI | D36: Lista | E36: MP / IN / SE / PT / RV. Ver criterio arriba. Define como se comporta el artículo en todo el sistema.
A37: CLASIFICACION | B37: FAMILIA | C37: SI | D37: Lista | E37: Agrupación de primer nivel para análisis de venta, compra y rotación.
A38: CLASIFICACION | B38: SUBFAMILIA | C38: No | D38: Lista | E38: Segundo nivel de detalle. Útil para informes finos y para el conteo cíclico.
A39: CLASIFICACION | B39: SECCION | C39: SI | D39: Lista | E39: Área operativa responsable del artículo (panadería, obrador, salados, cafetería).
A40: CLASIFICACION | B40: ES_COMPRABLE | C40: SI | D40: Lista | E40: SI = puede aparecer en un pedido a proveedor. Evita que alguien intente comprar un producto de obrador.
A41: CLASIFICACION | B41: ES_ELABORADO | C41: SI | D41: Lista | E41: SI = se produce internamente. Marca los artículos que generarán órdenes de producción.
A42: CLASIFICACION | B42: ES_VENDIBLE | C42: SI | D42: Lista | E42: SI = puede aparecer en una venta. Evita que se venda por error una materia prima.
... A84: ESTADO | B84: OBSERVACIONES | C84: No | D84: Captura | E84: Notas internas: condiciones del proveedor, estacionalidad, restricciones de producción.

Sheet MAESTRO_PRODUCTOS
A1: IDENTIFICACION | E1: CLASIFICACION | M1: UNIDADES DE MEDIDA | T1: COMPRAS | AA1: FISCAL Y PRECIOS | AD1: POLITICA DE PRECIO | AN1: CONTROL DE INVENTARIO | AU1: TRAZABILIDAD Y SEG. ALIMENTARIA | AY1: ESTADO
A2: CODIGO | B2: COD_BARRAS_EAN | C2: DESCRIPCION_TPV | D2: DESCRIPCION_COMPLETA | E2: TIPO_ARTICULO | F2: FAMILIA | G2: SUBFAMILIA | H2: SECCION | I2: ES_COMPRABLE | J2: ES_ELABORADO | K2: ES_VENDIBLE | L2: LLEVA_RECETA | M2: UM_BASE_STOCK | N2: UM_COMPRA | O2: FACTOR_COMPRA_A_BASE | P2: UM_VENTA | Q2: FACTOR_VENTA_A_BASE | R2: PESO_NETO_UD_G | S2: FORMATO_PRESENTACION | T2: COD_PROVEEDOR | U2: REF_PROVEEDOR | V2: PRECIO_COMPRA_SIN_IVA | W2: COSTE_UM_BASE | X2: PLAZO_ENTREGA_DIAS | Y2: PEDIDO_MINIMO | Z2: MERMA_ESTANDAR_% | AA2: COD_IVA | AB2: IVA_% | AC2: COSTE_UD_VENTA | AD2: METODO_PRECIO | AE2: MARGEN_OBJETIVO_% | AF2: PVP_OBJETIVO_CON_IVA | AG2: PVP_FIJO_CON_IVA | AH2: PVP_APLICADO_CON_IVA | AI2: PVP_APLICADO_SIN_IVA | AJ2: MARGEN_REAL_% | AK2: DESVIACION_PP | AL2: DIFERENCIA_EUR_UD | AM2: DIAGNOSTICO_PRECIO | AN2: CONTROLA_STOCK | AO2: METODO_VALORACION | AP2: STOCK_MINIMO | AQ2: STOCK_MAXIMO | AR2: PUNTO_PEDIDO | AS2: UBICACION | AT2: CLASE_ABC | AU2: CONTROL_LOTE | AV2: VIDA_UTIL_DIAS | AW2: CONSERVACION | AX2: ALERGENOS | AY2: ESTADO | AZ2: FECHA_ALTA | BA2: OBSERVACIONES
A3: MP-HAR-001 | C3: Harina trigo W180 | D3: Harina de trigo panificable W-180, saco 25 kg | E3: MP | F3: Harinas y sémolas | G3: Trigo | H3: Panadería | I3: SI | J3: NO | K3: NO | L3: NO | M3: kg | N3: saco | O3: 25 | S3: Saco 25 kg | T3: PRV-001 | U3: H180-25 | V3: 18.5 | W3: =IF(V3="","",IFERROR(V3/O3,"")) -> 0.74 | X3: 3 | Y3: 2 | Z3: 1 | AA3: SR4 | AB3: =IFERROR(INDEX(TABLA_IVA!$C$3:$C$6,MATCH(AA3,TABLA_IVA!$A$3:$A$6,0)),"") -> 0.04 | AF3: =IF(OR(AC3="",AE3="",AB3=""),"",IFERROR(AC3/(1-AE3)*(1+AB3),"")) | AH3: =IF(AD3="FIJO",IF(AG3="","",AG3),IF(AF3<>"",AF3,IF(AG3="","",AG3))) | AI3: =IF(OR(AH3="",AB3=""),"",IFERROR(AH3/(1+AB3),"")) | AJ3: =IF(OR(AI3="",AC3=""),"",IFERROR((AI3-AC3)/AI3,"")) | AK3: =IF(OR(AJ3="",AE3=""),"",AJ3-AE3) | AL3: =IF(OR(AH3="",AF3=""),"",AH3-AF3) | AM3: =IF(OR(A3="",K3<>"SI"),"",IF(AE3="","Sin objetivo",IF(AJ3="","Faltan datos",IF(AJ3<0,"PÉRDIDA",IF(AK3<-UMB_CRITICO,"MUY POR DEBAJO",IF(AK3<-UMB_BAJO,"POR DEBAJO",IF(AK3<-UMB_AJUSTADO,"AJUSTADO",IF(AK3<=UMB_ALTO,"EN OBJETIVO","POR ENCIMA")))))))) | AN3: SI | AO3: PMP | AP3: 50 | AQ3: 300 | AR3: 100 | AS3: Almacén seco | AT3: A | AU3: SI | AV3: 180 | AW3: Seco y ventilado | AX3: Gluten | AY3: Activo | AZ3: 46248
A4: MP-HAR-002 | C4: Harina de fuerza W300 | D4: Harina de fuerza W-300 para bollería, saco 25 kg | E4: MP | F4: Harinas y sémolas | G4: Trigo | H4: Pastelería/Obrador | I4: SI | J4: NO | K4: NO | L4: NO | M4: kg | N4: saco | O4: 25 | S4: Saco 25 kg | T4: PRV-001 | U4: H300-25 | V4: 22.9 | W4: =IF(V4="","",IFERROR(V4/O4,"")) -> 0.916 | X4: 3 | Y4: 2 | Z4: 1 | AA4: SR4 | AB4: =IFERROR(INDEX(TABLA_IVA!$C$3:$C$6,MATCH(AA4,TABLA_IVA!$A$3:$A$6,0)),"") -> 0.04 | AF4: =IF(OR(AC4="",AE4="",AB4=""),"",IFERROR(AC4/(1-AE4)*(1+AB4),"")) | AH4: =IF(AD4="FIJO",IF(AG4="","",AG4),IF(AF4<>"",AF4,IF(AG4="","",AG4))) | AI4: =IF(OR(AH4="",AB4=""),"",IFERROR(AH4/(1+AB4),"")) | AJ4: =IF(OR(AI4="",AC4=""),"",IFERROR((AI4-AC4)/AI4,"")) | AK4: =IF(OR(AJ4="",AE4=""),"",AJ4-AE4) | AL4: =IF(OR(AH4="",AF4=""),"",AH4-AF4) | AM4: =IF(OR(A4="",K4<>"SI"),"",IF(AE4="","Sin objetivo",IF(AJ4="","Faltan datos",IF(AJ4<0,"PÉRDIDA",IF(AK4<-UMB_CRITICO,"MUY POR DEBAJO",IF(AK4<-UMB_BAJO,"POR DEBAJO",IF(AK4<-UMB_AJUSTADO,"AJUSTADO",IF(AK4<=UMB_ALTO,"EN OBJETIVO","POR ENCIMA")))))))) | AN4: SI | AO4: PMP | AP4: 25 | AQ4: 150 | AR4: 50 | AS4: Almacén seco | AT4: A | AU4: SI | AV4: 180 | AW4: Seco y ventilado | AX4: Gluten | AY4: Activo | AZ4: 46248
A5: MP-LEV-001 | C5: Levadura fresca | D5: Levadura fresca prensada, bloque 500 g | E5: MP | F5: Levaduras y mejorantes | G5: Levadura | H5: Panadería | I5: SI | J5: NO | K5: NO | L5: NO | M5: kg | N5: caja | O5: 5 | S5: Caja 10 x 500 g | T5: PRV-001 | U5: LEV-500 | V5: 14 | W5: =IF(V5="","",IFERROR(V5/O5,"")) -> 2.8 | X5: 2 | Y5: 1 | Z5: 0.5 | AA5: RD10 | AB5: =IFERROR(INDEX(TABLA_IVA!$C$3:$C$6,MATCH(AA5,TABLA_IVA!$A$3:$A$6,0)),"") -> 0.1 | AF5: =IF(OR(AC5="",AE5="",AB5=""),"",IFERROR(AC5/(1-AE5)*(1+AB5),"")) | AH5: =IF(AD5="FIJO",IF(AG5="","",AG5),IF(AF5<>"",AF5,IF(AG5="","",AG5))) | AI5: =IF(OR(AH5="",AB5=""),"",IFERROR(AH5/(1+AB5),"")) | AJ5: =IF(OR(AI5="",AC5=""),"",IFERROR((AI5-AC5)/AI5,"")) | AK5: =IF(OR(AJ5="",AE5=""),"",AJ5-AE5) | AL5: =IF(OR(AH5="",AF5=""),"",AH5-AF5) | AM5: =IF(OR(A5="",K5<>"SI"),"",IF(AE5="","Sin objetivo",IF(AJ5="","Faltan datos",IF(AJ5<0,"PÉRDIDA",IF(AK5<-UMB_CRITICO,"MUY POR DEBAJO",IF(AK5<-UMB_BAJO,"POR DEBAJO",IF(AK5<-UMB_AJUSTADO,"AJUSTADO",IF(AK5<=UMB_ALTO,"EN OBJETIVO","POR ENCIMA")))))))) | AN5: SI | AO5: FIFO | AP5: 2 | AQ5: 10 | AR5: 4 | AS5: Cámara refrigeración | AT5: A | AU5: SI | AV5: 21 | AW5: Refrigerado (0-4 C) | AY5: Activo | AZ5: 46248
A6: MP-SAL-001 | C6: Sal marina fina | D6: Sal marina fina para panificación, saco 25 kg | E6: MP | F6: Sal y especias | G6: Otros | H6: Panadería | I6: SI | J6: NO | K6: NO | L6: NO | M6: kg | N6: saco | O6: 25 | S6: Saco 25 kg | T6: PRV-001 | U6: SAL-25 | V6: 9.2 | W6: =IF(V6="","",IFERROR(V6/O6,"")) -> 0.368 | X6: 5 | Y6: 1 | Z6: 0 | AA6: RD10 | AB6: =IFERROR(INDEX(TABLA_IVA!$C$3:$C$6,MATCH(AA6,TABLA_IVA!$A$3:$A$6,0)),"") -> 0.1 | AF6: =IF(OR(AC6="",AE6="",AB6=""),"",IFERROR(AC6/(1-AE6)*(1+AB6),"")) | AH6: =IF(AD6="FIJO",IF(AG6="","",AG6),IF(AF6<>"",AF6,IF(AG6="","",AG6))) | AI6: =IF(OR(AH6="",AB6=""),"",IFERROR(AH6/(1+AB6),"")) | AJ6: =IF(OR(AI6="",AC6=""),"",IFERROR((AI6-AC6)/AI6,"")) | AK6: =IF(OR(AJ6="",AE6=""),"",AJ6-AE6) | AL6: =IF(OR(AH6="",AF6=""),"",AH6-AF6) | AM6: =IF(OR(A6="",K6<>"SI"),"",IF(AE6="","Sin objetivo",IF(AJ6="","Faltan datos",IF(AJ6<0,"PÉRDIDA",IF(AK6<-UMB_CRITICO,"MUY POR DEBAJO",IF(AK6<-UMB_BAJO,"POR DEBAJO",IF(AK6<-UMB_AJUSTADO,"AJUSTADO",IF(AK6<=UMB_ALTO,"EN OBJETIVO","POR ENCIMA")))))))) | AN6: SI | AO6: PMP | AP6: 10 | AQ6: 50 | AR6: 20 | AS6: Almacén seco | AT6: C | AU6: NO | AV6: 720 | AW6: Seco y ventilado | AY6: Activo | AZ6: 46248
A7: MP-AZU-001 | C7: Azúcar blanquilla | D7: Azúcar blanquilla, saco 25 kg | E7: MP | F7: Azúcares y edulcorantes | G7: Azúcar | H7: Pastelería/Obrador | I7: SI | J7: NO | K7: NO | L7: NO | M7: kg | N7: saco | O7: 25 | S7: Saco 25 kg | T7: PRV-002 | U7: AZ-25 | V7: 24 | W7: =IF(V7="","",IFERROR(V7/O7,"")) -> 0.96 | X7: 3 | Y7: 1 | Z7: 0.5 | AA7: RD10 | AB7: =IFERROR(INDEX(TABLA_IVA!$C$3:$C$6,MATCH(AA7,TABLA_IVA!$A$3:$A$6,0)),"") -> 0.1 | AF7: =IF(OR(AC7="",AE7="",AB7=""),"",IFERROR(AC7/(1-AE7)*(1+AB7),"")) | AH7: =IF(AD7="FIJO",IF(AG7="","",AG7),IF(AF7<>"",AF7,IF(AG7="","",AG7))) | AI7: =IF(OR(AH7="",AB7=""),"",IFERROR(AH7/(1+AB7),"")) | AJ7: =IF(OR(AI7="",AC7=""),"",IFERROR((AI7-AC7)/AI7,"")) | AK7: =IF(OR(AJ7="",AE7=""),"",AJ7-AE7) | AL7: =IF(OR(AH7="",AF7=""),"",AH7-AF7) | AM7: =IF(OR(A7="",K7<>"SI"),"",IF(AE7="","Sin objetivo",IF(AJ7="","Faltan datos",IF(AJ7<0,"PÉRDIDA",IF(AK7<-UMB_CRITICO,"MUY POR DEBAJO",IF(AK7<-UMB_BAJO,"POR DEBAJO",IF(AK7<-UMB_AJUSTADO,"AJUSTADO",IF(AK7<=UMB_ALTO,"EN OBJETIVO","POR ENCIMA")))))))) | AN7: SI | AO7: PMP | AP7: 25 | AQ7: 100 | AR7: 40 | AS7: Almacén seco | AT7: B | AU7: NO | AV7: 540 | AW7: Seco y ventilado | AY7: Activo | AZ7: 46248
A8: MP-GRA-001 | C8: Mantequilla 82% | D8: Mantequilla sin sal 82% MG, pastilla 1 kg | E8: MP | F8: Grasas y aceites | G8: Mantequilla | H8: Pastelería/Obrador | I8: SI | J8: NO | K8: NO | L8: NO | M8: kg | N8: caja | O8: 10 | S8: Caja 10 kg | T8: PRV-002 | U8: MTQ-82 | V8: 78 | W8: =IF(V8="","",IFERROR(V8/O8,"")) -> 7.8 | X8: 3 | Y8: 1 | Z8: 1 | AA8: RD10 | AB8: =IFERROR(INDEX(TABLA_IVA!$C$3:$C$6,MATCH(AA8,TABLA_IVA!$A$3:$A$6,0)),"") -> 0.1 | AF8: =IF(OR(AC8="",AE8="",AB8=""),"",IFERROR(AC8/(1-AE8)*(1+AB8),"")) | AH8: =IF(AD8="FIJO",IF(AG8="","",AG8),IF(AF8<>"",AF8,IF(AG8="","",AG8))) | AI8: =IF(OR(AH8="",AB8=""),"",IFERROR(AH8/(1+AB8),"")) | AJ8: =IF(OR(AI8="",AC8=""),"",IFERROR((AI8-AC8)/AI8,"")) | AK8: =IF(OR(AJ8="",AE8=""),"",AJ8-AE8) | AL8: =IF(OR(AH8="",AF8=""),"",AH8-AF8) | AM8: =IF(OR(A8="",K8<>"SI"),"",IF(AE8="","Sin objetivo",IF(AJ8="","Faltan datos",IF(AJ8<0,"PÉRDIDA",IF(AK8<-UMB_CRITICO,"MUY POR DEBAJO",IF(AK8<-UMB_BAJO,"POR DEBAJO",IF(AK8<-UMB_AJUSTADO,"AJUSTADO",IF(AK8<=UMB_ALTO,"EN OBJETIVO","POR ENCIMA")))))))) | AN8: SI | AO8: FIFO | AP8: 10 | AQ8: 40 | AR8: 15 | AS8: Cámara refrigeración | AT8: A | AU8: SI | AV8: 90 | AW8: Refrigerado (0-4 C) | AX8: Leche | AY8: Activo | AZ8: 46248
A9: MP-GRA-002 | C9: Margarina hojaldre | D9: Margarina especial hojaldre en placa 2 kg | E9: MP | F9: Grasas y aceites | G9: Margarina | H9: Pastelería/Obrador | I9: SI | J9: NO | K9: NO | L9: NO | M9: kg | N9: caja | O9: 10 | S9: Caja 5 x 2 kg | T9: PRV-002 | U9: MRG-HOJ | V9: 32.5 | W9: =IF(V9="","",IFERROR(V9/O9,"")) -> 3.25 | X9: 4 | Y9: 1 | Z9: 1 | AA9: RD10 | AB9: =IFERROR(INDEX(TABLA_IVA!$C$3:$C$6,MATCH(AA9,TABLA_IVA!$A$3:$A$6,0)),"") -> 0.1 | AF9: =IF(OR(AC9="",AE9="",AB9=""),"",IFERROR(AC9/(1-AE9)*(1+AB9),"")) | AH9: =IF(AD9="FIJO",IF(AG9="","",AG9),IF(AF9<>"",AF9,IF(AG9="","",AG9))) | AI9: =IF(OR(AH9="",AB9=""),"",IFERROR(AH9/(1+AB9),"")) | AJ9: =IF(OR(AI9="",AC9=""),"",IFERROR((AI9-AC9)/AI9,"")) | AK9: =IF(OR(AJ9="",AE9=""),"",AJ9-AE9) | AL9: =IF(OR(AH9="",AF9=""),"",AH9-AF9) | AM9: =IF(OR(A9="",K9<>"SI"),"",IF(AE9="","Sin objetivo",IF(AJ9="","Faltan datos",IF(AJ9<0,"PÉRDIDA",IF(AK9<-UMB_CRITICO,"MUY POR DEBAJO",IF(AK9<-UMB_BAJO,"POR DEBAJO",IF(AK9<-UMB_AJUSTADO,"AJUSTADO",IF(AK9<=UMB_ALTO,"EN OBJETIVO","POR ENCIMA")))))))) | AN9: SI | AO9: FIFO | AP9: 5 | AQ9: 30 | AR9: 10 | AS9: Cámara refrigeración | AT9: B | AU9: SI | AV9: 120 | AW9: Refrigerado (0-4 C) | AY9: Activo | AZ9: 46248
A10: MP-LAC-001 | C10: Leche entera UHT | D10: Leche entera UHT, brick 1 l | E10: MP | F10: Lácteos y huevos | G10: Leche | H10: Pastelería/Obrador | I10: SI | J10: NO | K10: NO | L10: NO | M10: l | N10: caja | O10: 12 | S10: Caja 12 x 1 l | T10: PRV-002 | U10: LEC-UHT | V10: 10.8 | W10: =IF(V10="","",IFERROR(V10/O10,"")) -> 0.9 | X10: 3 | Y10: 1 | Z10: 0 | AA10: SR4 | AB10: =IFERROR(INDEX(TABLA_IVA!$C$3:$C$6,MATCH(AA10,TABLA_IVA!$A$3:$A$6,0)),"") -> 0.04 | AF10: =IF(OR(AC10="",AE10="",AB10=""),"",IFERROR(AC10/(1-AE10)*(1+AB10),"")) | AH10: =IF(AD10="FIJO",IF(AG10="","",AG10),IF(AF10<>"",AF10,IF(AG10="","",AG10))) | AI10: =IF(OR(AH10="",AB10=""),"",IFERROR(AH10/(1+AB10),"")) | AJ10: =IF(OR(AI10="",AC10=""),"",IFERROR((AI10-AC10)/AI10,"")) | AK10: =IF(OR(AJ10="",AE10=""),"",AJ10-AE10) | AL10: =IF(OR(AH10="",AF10=""),"",AH10-AF10) | AM10: =IF(OR(A10="",K10<>"SI"),"",IF(AE10="","Sin objetivo",IF(AJ10="","Faltan datos",IF(AJ10<0,"PÉRDIDA",IF(AK10<-UMB_CRITICO,"MUY POR DEBAJO",IF(AK10<-UMB_BAJO,"POR DEBAJO",IF(AK10<-UMB_AJUSTADO,"AJUSTADO",IF(AK10<=UMB_ALTO,"EN OBJETIVO","POR ENCIMA")))))))) | AN10: SI | AO10: FIFO | AP10: 12 | AQ10: 60 | AR10: 24 | AS10: Almacén seco | AT10: B | AU10: SI | AV10: 120 | AW10: Ambiente | AX10: Leche | AY10: Activo | AZ10: 46248
A11: MP-LAC-002 | C11: Nata 35% MG | D11: Nata para montar 35% MG, brick 1 l | E11: MP | F11: Lácteos y huevos | G11: Nata | H11: Pastelería/Obrador | I11: SI | J11: NO | K11: NO | L11: NO | M11: l | N11: caja | O11: 12 | S11: Caja 12 x 1 l | T11: PRV-002 | U11: NAT-35 | V11: 29.4 | W11: =IF(V11="","",IFERROR(V11/O11,"")) -> 2.45 | X11: 3 | Y11: 1 | Z11: 1 | AA11: RD10 | AB11: =IFERROR(INDEX(TABLA_IVA!$C$3:$C$6,MATCH(AA11,TABLA_IVA!$A$3:$A$6,0)),"") -> 0.1 | AF11: =IF(OR(AC11="",AE11="",AB11=""),"",IFERROR(AC11/(1-AE11)*(1+AB11),"")) | AH11: =IF(AD11="FIJO",IF(AG11="","",AG11),IF(AF11<>"",AF11,IF(AG11="","",AG11))) | AI11: =IF(OR(AH11="",AB11=""),"",IFERROR(AH11/(1+AB11),"")) | AJ11: =IF(OR(AI11="",AC11=""),"",IFERROR((AI11-AC11)/AI11,"")) | AK11: =IF(OR(AJ11="",AE11=""),"",AJ11-AE11) | AL11: =IF(OR(AH11="",AF11=""),"",AH11-AF11) | AM11: =IF(OR(A11="",K11<>"SI"),"",IF(AE11="","Sin objetivo",IF(AJ11="","Faltan datos",IF(AJ11<0,"PÉRDIDA",IF(AK11<-UMB_CRITICO,"MUY POR DEBAJO",IF(AK11<-UMB_BAJO,"POR DEBAJO",IF(AK11<-UMB_AJUSTADO,"AJUSTADO",IF(AK11<=UMB_ALTO,"EN OBJETIVO","POR ENCIMA")))))))) | AN11: SI | AO11: FIFO | AP11: 6 | AQ11: 36 | AR11: 12 | AS11: Cámara refrigeración | AT11: A | AU11: SI | AV11: 45 | AW11: Refrigerado (0-4 C) | AX11: Leche | AY11: Activo | AZ11: 46248
A12: MP-LAC-003 | C12: Huevo líquido pasteurizado | D12: Huevo líquido entero pasteurizado, garrafa 5 kg | E12: MP | F12: Lácteos y huevos | G12: Huevo | H12: Pastelería/Obrador | I12: SI | J12: NO | K12: NO | L12: NO | M12: kg | N12: bote | O12: 5 | S12: Garrafa 5 kg | T12: PRV-002 | U12: HUE-LIQ | V12: 21 | W12: =IF(V12="","",IFERROR(V12/O12,"")) -> 4.2 | X12: 3 | Y12: 1 | Z12: 0.5 | AA12: SR4 | AB12: =IFERROR(INDEX(TABLA_IVA!$C$3:$C$6,MATCH(AA12,TABLA_IVA!$A$3:$A$6,0)),"") -> 0.04 | AF12: =IF(OR(AC12="",AE12="",AB12=""),"",IFERROR(AC12/(1-AE12)*(1+AB12),"")) | AH12: =IF(AD12="FIJO",IF(AG12="","",AG12),IF(AF12<>"",AF12,IF(AG12="","",AG12))) | AI12: =IF(OR(AH12="",AB12=""),"",IFERROR(AH12/(1+AB12),"")) | AJ12: =IF(OR(AI12="",AC12=""),"",IFERROR((AI12-AC12)/AI12,"")) | AK12: =IF(OR(AJ12="",AE12=""),"",AJ12-AE12) | AL12: =IF(OR(AH12="",AF12=""),"",AH12-AF12) | AM12: =IF(OR(A12="",K12<>"SI"),"",IF(AE12="","Sin objetivo",IF(AJ12="","Faltan datos",IF(AJ12<0,"PÉRDIDA",IF(AK12<-UMB_CRITICO,"MUY POR DEBAJO",IF(AK12<-UMB_BAJO,"POR DEBAJO",IF(AK12<-UMB_AJUSTADO,"AJUSTADO",IF(AK12<=UMB_ALTO,"EN OBJETIVO","POR ENCIMA")))))))) | AN12: SI | AO12: FIFO | AP12: 5 | AQ12: 25 | AR12: 10 | AS12: Cámara refrigeración | AT12: A | AU12: SI | AV12: 30 | AW12: Refrigerado (0-4 C) | AX12: Huevos | AY12: Activo | AZ12: 46248
A13: MP-CHO-001 | C13: Cobertura negra 55% | D13: Cobertura de chocolate negro 55% cacao, en gotas | E13: MP | F13: Chocolates y coberturas | G13: Cobertura | H13: Pastelería/Obrador | I13: SI | J13: NO | K13: NO | L13: NO | M13: kg | N13: caja | O13: 5 | S13: Caja 5 kg | T13: PRV-002 | U13: COB-55 | V13: 41 | W13: =IF(V13="","",IFERROR(V13/O13,"")) -> 8.2 | X13: 5 | Y13: 1 | Z13: 0.5 | AA13: RD10 | AB13: =IFERROR(INDEX(TABLA_IVA!$C$3:$C$6,MATCH(AA13,TABLA_IVA!$A$3:$A$6,0)),"") -> 0.1 | AF13: =IF(OR(AC13="",AE13="",AB13=""),"",IFERROR(AC13/(1-AE13)*(1+AB13),"")) | AH13: =IF(AD13="FIJO",IF(AG13="","",AG13),IF(AF13<>"",AF13,IF(AG13="","",AG13))) | AI13: =IF(OR(AH13="",AB13=""),"",IFERROR(AH13/(1+AB13),"")) | AJ13: =IF(OR(AI13="",AC13=""),"",IFERROR((AI13-AC13)/AI13,"")) | AK13: =IF(OR(AJ13="",AE13=""),"",AJ13-AE13) | AL13: =IF(OR(AH13="",AF13=""),"",AH13-AF13) | AM13: =IF(OR(A13="",K13<>"SI"),"",IF(AE13="","Sin objetivo",IF(AJ13="","Faltan datos",IF(AJ13<0,"PÉRDIDA",IF(AK13<-UMB_CRITICO,"MUY POR DEBAJO",IF(AK13<-UMB_BAJO,"POR DEBAJO",IF(AK13<-UMB_AJUSTADO,"AJUSTADO",IF(AK13<=UMB_ALTO,"EN OBJETIVO","POR ENCIMA")))))))) | AN13: SI | AO13: PMP | AP13: 5 | AQ13: 20 | AR13: 8 | AS13: Almacén seco | AT13: A | AU13: SI | AV13: 365 | AW13: Seco y ventilado | AX13: Soja;Leche | AY13: Activo | AZ13: 46248 | BA13: Trazas de leche
A14: MP-FRU-001 | C14: Almendra molida | D14: Almendra cruda molida, bolsa 1 kg | E14: MP | F14: Frutas y frutos secos | G14: Frutos secos | H14: Pastelería/Obrador | I14: SI | J14: NO | K14: NO | L14: NO | M14: kg | N14: paquete | O14: 1 | S14: Bolsa 1 kg | T14: PRV-002 | U14: ALM-MOL | V14: 9.8 | W14: =IF(V14="","",IFERROR(V14/O14,"")) -> 9.8 | X14: 5 | Y14: 5 | Z14: 1 | AA14: RD10 | AB14: =IFERROR(INDEX(TABLA_IVA!$C$3:$C$6,MATCH(AA14,TABLA_IVA!$A$3:$A$6,0)),"") -> 0.1 | AF14: =IF(OR(AC14="",AE14="",AB14=""),"",IFERROR(AC14/(1-AE14)*(1+AB14),"")) | AH14: =IF(AD14="FIJO",IF(AG14="","",AG14),IF(AF14<>"",AF14,IF(AG14="","",AG14))) | AI14: =IF(OR(AH14="",AB14=""),"",IFERROR(AH14/(1+AB14),"")) | AJ14: =IF(OR(AI14="",AC14=""),"",IFERROR((AI14-AC14)/AI14,"")) | AK14: =IF(OR(AJ14="",AE14=""),"",AJ14-AE14) | AL14: =IF(OR(AH14="",AF14=""),"",AH14-AF14) | AM14: =IF(OR(A14="",K14<>"SI"),"",IF(AE14="","Sin objetivo",IF(AJ14="","Faltan datos",IF(AJ14<0,"PÉRDIDA",IF(AK14<-UMB_CRITICO,"MUY POR DEBAJO",IF(AK14<-UMB_BAJO,"POR DEBAJO",IF(AK14<-UMB_AJUSTADO,"AJUSTADO",IF(AK14<=UMB_ALTO,"EN OBJETIVO","POR ENCIMA")))))))) | AN14: SI | AO14: PMP | AP14: 3 | AQ14: 15 | AR14: 5 | AS14: Almacén seco | AT14: B | AU14: SI | AV14: 180 | AW14: Seco y ventilado | AX14: Frutos de cáscara | AY14: Activo | AZ14: 46248
A15: IN-ENV-001 | C15: Bolsa papel antigrasa | D15: Bolsa de papel antigrasa para pan, 14 x 30 cm | E15: IN | F15: Envases y embalajes | G15: Bolsas y papel | H15: General | I15: SI | J15: NO | K15: NO | L15: NO | M15: ud | N15: caja | O15: 1000 | S15: Caja 1.000 ud | T15: PRV-003 | U15: BOL-1430 | V15: 42 | W15: =IF(V15="","",IFERROR(V15/O15,"")) -> 0.042 | X15: 7 | Y15: 1 | Z15: 1 | AA15: GN21 | AB15: =IFERROR(INDEX(TABLA_IVA!$C$3:$C$6,MATCH(AA15,TABLA_IVA!$A$3:$A$6,0)),"") -> 0.21 | AF15: =IF(OR(AC15="",AE15="",AB15=""),"",IFERROR(AC15/(1-AE15)*(1+AB15),"")) | AH15: =IF(AD15="FIJO",IF(AG15="","",AG15),IF(AF15<>"",AF15,IF(AG15="","",AG15))) | AI15: =IF(OR(AH15="",AB15=""),"",IFERROR(AH15/(1+AB15),"")) | AJ15: =IF(OR(AI15="",AC15=""),"",IFERROR((AI15-AC15)/AI15,"")) | AK15: =IF(OR(AJ15="",AE15=""),"",AJ15-AE15) | AL15: =IF(OR(AH15="",AF15=""),"",AH15-AF15) | AM15: =IF(OR(A15="",K15<>"SI"),"",IF(AE15="","Sin objetivo",IF(AJ15="","Faltan datos",IF(AJ15<0,"PÉRDIDA",IF(AK15<-UMB_CRITICO,"MUY POR DEBAJO",IF(AK15<-UMB_BAJO,"POR DEBAJO",IF(AK15<-UMB_AJUSTADO,"AJUSTADO",IF(AK15<=UMB_ALTO,"EN OBJETIVO","POR ENCIMA")))))))) | AN15: SI | AO15: PMP | AP15: 1000 | AQ15: 6000 | AR15: 2000 | AS15: Trastienda | AT15: B | AU15: NO | AW15: Seco y ventilado | AY15: Activo | AZ15: 46248
A16: IN-ENV-002 | C16: Caja tarta 26 cm | D16: Caja de cartón para tarta redonda 26 cm | E16: IN | F16: Envases y embalajes | G16: Cajas | H16: Pastelería/Obrador | I16: SI | J16: NO | K16: NO | L16: NO | M16: ud | N16: caja | O16: 100 | S16: Paquete 100 ud | T16: PRV-003 | U16: CJT-26 | V16: 28 | W16: =IF(V16="","",IFERROR(V16/O16,"")) -> 0.28 | X16: 7 | Y16: 1 | Z16: 0 | AA16: GN21 | AB16: =IFERROR(INDEX(TABLA_IVA!$C$3:$C$6,MATCH(AA16,TABLA_IVA!$A$3:$A$6,0)),"") -> 0.21 | AF16: =IF(OR(AC16="",AE16="",AB16=""),"",IFERROR(AC16/(1-AE16)*(1+AB16),"")) | AH16: =IF(AD16="FIJO",IF(AG16="","",AG16),IF(AF16<>"",AF16,IF(AG16="","",AG16))) | AI16: =IF(OR(AH16="",AB16=""),"",IFERROR(AH16/(1+AB16),"")) | AJ16: =IF(OR(AI16="",AC16=""),"",IFERROR((AI16-AC16)/AI16,"")) | AK16: =IF(OR(AJ16="",AE16=""),"",AJ16-AE16) | AL16: =IF(OR(AH16="",AF16=""),"",AH16-AF16) | AM16: =IF(OR(A16="",K16<>"SI"),"",IF(AE16="","Sin objetivo",IF(AJ16="","Faltan datos",IF(AJ16<0,"PÉRDIDA",IF(AK16<-UMB_CRITICO,"MUY POR DEBAJO",IF(AK16<-UMB_BAJO,"POR DEBAJO",IF(AK16<-UMB_AJUSTADO,"AJUSTADO",IF(AK16<=UMB_ALTO,"EN OBJETIVO","POR ENCIMA")))))))) | AN16: SI | AO16: PMP | AP16: 100 | AQ16: 500 | AR16: 200 | AS16: Trastienda | AT16: C | AU16: NO | AW16: Seco y ventilado | AY16: Activo | AZ16: 46248
A17: IN-ENV-003 | C17: Etiqueta ingredientes | D17: Etiqueta adhesiva de ingredientes y alérgenos | E17: IN | F17: Envases y embalajes | G17: Etiquetas | H17: General | I17: SI | J17: NO | K17: NO | L17: NO | M17: ud | N17: paquete | O17: 500 | S17: Rollo 500 ud | T17: PRV-003 | U17: ETQ-ING | V17: 12 | W17: =IF(V17="","",IFERROR(V17/O17,"")) -> 0.024 | X17: 10 | Y17: 1 | Z17: 0 | AA17: GN21 | AB17: =IFERROR(INDEX(TABLA_IVA!$C$3:$C$6,MATCH(AA17,TABLA_IVA!$A$3:$A$6,0)),"") -> 0.21 | AF17: =IF(OR(AC17="",AE17="",AB17=""),"",IFERROR(AC17/(1-AE17)*(1+AB17),"")) | AH17: =IF(AD17="FIJO",IF(AG17="","",AG17),IF(AF17<>"",AF17,IF(AG17="","",AG17))) | AI17: =IF(OR(AH17="",AB17=""),"",IFERROR(AH17/(1+AB17),"")) | AJ17: =IF(OR(AI17="",AC17=""),"",IFERROR((AI17-AC17)/AI17,"")) | AK17: =IF(OR(AJ17="",AE17=""),"",AJ17-AE17) | AL17: =IF(OR(AH17="",AF17=""),"",AH17-AF17) | AM17: =IF(OR(A17="",K17<>"SI"),"",IF(AE17="","Sin objetivo",IF(AJ17="","Faltan datos",IF(AJ17<0,"PÉRDIDA",IF(AK17<-UMB_CRITICO,"MUY POR DEBAJO",IF(AK17<-UMB_BAJO,"POR DEBAJO",IF(AK17<-UMB_AJUSTADO,"AJUSTADO",IF(AK17<=UMB_ALTO,"EN OBJETIVO","POR ENCIMA")))))))) | AN17: SI | AO17: PMP | AP17: 500 | AQ17: 3000 | AR17: 1000 | AS17: Trastienda | AT17: C | AU17: NO | AW17: Ambiente | AY17: Activo | AZ17: 46248 | BA17: Obligatoria en producto envasado
A18: SE-SEM-001 | C18: Masa madre líquida | D18: Masa madre líquida de trigo, elaboración propia | E18: SE | F18: Semielaborados | G18: Masas | H18: Panadería | I18: NO | J18: SI | K18: NO | L18: SI | M18: kg | S18: Cubo 10 kg | W18: =IF(V18="","",IFERROR(V18/O18,"")) | Z18: 2 | AA18: SR4 | AB18: =IFERROR(INDEX(TABLA_IVA!$C$3:$C$6,MATCH(AA18,TABLA_IVA!$A$3:$A$6,0)),"") -> 0.04 | AF18: =IF(OR(AC18="",AE18="",AB18=""),"",IFERROR(AC18/(1-AE18)*(1+AB18),"")) | AH18: =IF(AD18="FIJO",IF(AG18="","",AG18),IF(AF18<>"",AF18,IF(AG18="","",AG18))) | AI18: =IF(OR(AH18="",AB18=""),"",IFERROR(AH18/(1+AB18),"")) | AJ18: =IF(OR(AI18="",AC18=""),"",IFERROR((AI18-AC18)/AI18,"")) | AK18: =IF(OR(AJ18="",AE18=""),"",AJ18-AE18) | AL18: =IF(OR(AH18="",AF18=""),"",AH18-AF18) | AM18: =IF(OR(A18="",K18<>"SI"),"",IF(AE18="","Sin objetivo",IF(AJ18="","Faltan datos",IF(AJ18<0,"PÉRDIDA",IF(AK18<-UMB_CRITICO,"MUY POR DEBAJO",IF(AK18<-UMB_BAJO,"POR DEBAJO",IF(AK18<-UMB_AJUSTADO,"AJUSTADO",IF(AK18<=UMB_ALTO,"EN OBJETIVO","POR ENCIMA")))))))) | AN18: SI | AO18: PMP | AP18: 5 | AQ18: 30 | AR18: 10 | AS18: Cámara refrigeración | AT18: A | AU18: SI | AV18: 5 | AW18: Refrigerado (0-4 C) | AX18: Gluten | AY18: Activo | AZ18: 46248 | BA18: Refresco diario
A19: SE-SEM-002 | C19: Masa de hojaldre | D19: Masa de hojaldre laminada, elaboración propia | E19: SE | F19: Semielaborados | G19: Masas | H19: Pastelería/Obrador | I19: NO | J19: SI | K19: NO | L19: SI | M19: kg | S19: Placa 2 kg | W19: =IF(V19="","",IFERROR(V19/O19,"")) | Z19: 3 | AA19: RD10 | AB19: =IFERROR(INDEX(TABLA_IVA!$C$3:$C$6,MATCH(AA19,TABLA_IVA!$A$3:$A$6,0)),"") -> 0.1 | AF19: =IF(OR(AC19="",AE19="",AB19=""),"",IFERROR(AC19/(1-AE19)*(1+AB19),"")) | AH19: =IF(AD19="FIJO",IF(AG19="","",AG19),IF(AF19<>"",AF19,IF(AG19="","",AG19))) | AI19: =IF(OR(AH19="",AB19=""),"",IFERROR(AH19/(1+AB19),"")) | AJ19: =IF(OR(AI19="",AC19=""),"",IFERROR((AI19-AC19)/AI19,"")) | AK19: =IF(OR(AJ19="",AE19=""),"",AJ19-AE19) | AL19: =IF(OR(AH19="",AF19=""),"",AH19-AF19) | AM19: =IF(OR(A19="",K19<>"SI"),"",IF(AE19="","Sin objetivo",IF(AJ19="","Faltan datos",IF(AJ19<0,"PÉRDIDA",IF(AK19<-UMB_CRITICO,"MUY POR DEBAJO",IF(AK19<-UMB_BAJO,"POR DEBAJO",IF(AK19<-UMB_AJUSTADO,"AJUSTADO",IF(AK19<=UMB_ALTO,"EN OBJETIVO","POR ENCIMA")))))))) | AN19: SI | AO19: FIFO | AP19: 4 | AQ19: 20 | AR19: 8 | AS19: Congelador | AT19: A | AU19: SI | AV19: 60 | AW19: Congelado (-18 C) | AX19: Gluten;Leche | AY19: Activo | AZ19: 46248
A20: SE-SEM-003 | C20: Crema pastelera | D20: Crema pastelera, elaboración propia | E20: SE | F20: Semielaborados | G20: Cremas y rellenos | H20: Pastelería/Obrador | I20: NO | J20: SI | K20: NO | L20: SI | M20: kg | S20: Cubeta 5 kg | W20: =IF(V20="","",IFERROR(V20/O20,"")) | Z20: 2 | AA20: RD10 | AB20: =IFERROR(INDEX(TABLA_IVA!$C$3:$C$6,MATCH(AA20,TABLA_IVA!$A$3:$A$6,0)),"") -> 0.1 | AF20: =IF(OR(AC20="",AE20="",AB20=""),"",IFERROR(AC20/(1-AE20)*(1+AB20),"")) | AH20: =IF(AD20="FIJO",IF(AG20="","",AG20),IF(AF20<>"",AF20,IF(AG20="","",AG20))) | AI20: =IF(OR(AH20="",AB20=""),"",IFERROR(AH20/(1+AB20),"")) | AJ20: =IF(OR(AI20="",AC20=""),"",IFERROR((AI20-AC20)/AI20,"")) | AK20: =IF(OR(AJ20="",AE20=""),"",AJ20-AE20) | AL20: =IF(OR(AH20="",AF20=""),"",AH20-AF20) | AM20: =IF(OR(A20="",K20<>"SI"),"",IF(AE20="","Sin objetivo",IF(AJ20="","Faltan datos",IF(AJ20<0,"PÉRDIDA",IF(AK20<-UMB_CRITICO,"MUY POR DEBAJO",IF(AK20<-UMB_BAJO,"POR DEBAJO",IF(AK20<-UMB_AJUSTADO,"AJUSTADO",IF(AK20<=UMB_ALTO,"EN OBJETIVO","POR ENCIMA")))))))) | AN20: SI | AO20: FIFO | AP20: 3 | AQ20: 15 | AR20: 5 | AS20: Cámara refrigeración | AT20: A | AU20: SI | AV20: 3 | AW20: Refrigerado (0-4 C) | AX20: Leche;Huevos;Gluten | AY20: Activo | AZ20: 46248 | BA20: Producto de alto riesgo APPCC
A21: SE-SEM-004 | C21: Plancha bizcocho genovés | D21: Plancha de bizcocho genovés 40x60, elaboración propia | E21: SE | F21: Semielaborados | G21: Bizcochos | H21: Pastelería/Obrador | I21: NO | J21: SI | K21: NO | L21: SI | M21: ud | R21: 600 | S21: Plancha 40x60 | W21: =IF(V21="","",IFERROR(V21/O21,"")) | Z21: 4 | AA21: RD10 | AB21: =IFERROR(INDEX(TABLA_IVA!$C$3:$C$6,MATCH(AA21,TABLA_IVA!$A$3:$A$6,0)),"") -> 0.1 | AF21: =IF(OR(AC21="",AE21="",AB21=""),"",IFERROR(AC21/(1-AE21)*(1+AB21),"")) | AH21: =IF(AD21="FIJO",IF(AG21="","",AG21),IF(AF21<>"",AF21,IF(AG21="","",AG21))) | AI21: =IF(OR(AH21="",AB21=""),"",IFERROR(AH21/(1+AB21),"")) | AJ21: =IF(OR(AI21="",AC21=""),"",IFERROR((AI21-AC21)/AI21,"")) | AK21: =IF(OR(AJ21="",AE21=""),"",AJ21-AE21) | AL21: =IF(OR(AH21="",AF21=""),"",AH21-AF21) | AM21: =IF(OR(A21="",K21<>"SI"),"",IF(AE21="","Sin objetivo",IF(AJ21="","Faltan datos",IF(AJ21<0,"PÉRDIDA",IF(AK21<-UMB_CRITICO,"MUY POR DEBAJO",IF(AK21<-UMB_BAJO,"POR DEBAJO",IF(AK21<-UMB_AJUSTADO,"AJUSTADO",IF(AK21<=UMB_ALTO,"EN OBJETIVO","POR ENCIMA")))))))) | AN21: SI | AO21: FIFO | AP21: 5 | AQ21: 30 | AR21: 10 | AS21: Congelador | AT21: B | AU21: SI | AV21: 30 | AW21: Congelado (-18 C) | AX21: Gluten;Huevos | AY21: Activo | AZ21: 46248
A22: PT-PAN-001 | B22: 8400000000018 | C22: Barra rústica 250 g | D22: Barra de pan rústico de masa madre, 250 g | E22: PT | F22: Pan | G22: Barra | H22: Panadería | I22: NO | J22: SI | K22: SI | L22: SI | M22: ud | P22: ud | Q22: 1 | R22: 250 | S22: Unidad 250 g | W22: =IF(V22="","",IFERROR(V22/O22,"")) | Z22: 3 | AA22: SR4 | AB22: =IFERROR(INDEX(TABLA_IVA!$C$3:$C$6,MATCH(AA22,TABLA_IVA!$A$3:$A$6,0)),"") -> 0.04 | AC22: 0.28 | AD22: FIJO | AE22: 0.75 | AF22: =IF(OR(AC22="",AE22="",AB22=""),"",IFERROR(AC22/(1-AE22)*(1+AB22),"")) -> 1.1648 | AG22: 1.2 | AH22: =IF(AD22="FIJO",IF(AG22="","",AG22),IF(AF22<>"",AF22,IF(AG22="","",AG22))) -> 1.2 | AI22: =IF(OR(AH22="",AB22=""),"",IFERROR(AH22/(1+AB22),"")) -> 1.1538462 | AJ22: =IF(OR(AI22="",AC22=""),"",IFERROR((AI22-AC22)/AI22,"")) -> 0.75733333 | AK22: =IF(OR(AJ22="",AE22=""),"",AJ22-AE22) -> 0.0073333333 | AL22: =IF(OR(AH22="",AF22=""),"",AH22-AF22) -> 0.0352 | AM22: =IF(OR(A22="",K22<>"SI"),"",IF(AE22="","Sin objetivo",IF(AJ22="","Faltan datos",IF(AJ22<0,"PÉRDIDA",IF(AK22<-UMB_CRITICO,"MUY POR DEBAJO",IF(AK22<-UMB_BAJO,"POR DEBAJO",IF(AK22<-UMB_AJUSTADO,"AJUSTADO",IF(AK22<=UMB_ALTO,"EN OBJETIVO","POR ENCIMA")))))))) -> EN OBJETIVO | AN22: SI | AO22: FIFO | AP22: 0 | AQ22: 0 | AR22: 0 | AS22: Tienda / vitrina | AT22: A | AU22: SI | AV22: 1 | AW22: Ambiente | AX22: Gluten | AY22: Activo | AZ22: 46248
A23: PT-PAN-002 | B23: 8400000000025 | C23: Hogaza integral 500 g | D23: Hogaza de trigo integral con masa madre, 500 g | E23: PT | F23: Pan | G23: Hogaza | H23: Panadería | I23: NO | J23: SI | K23: SI | L23: SI | M23: ud | P23: ud | Q23: 1 | R23: 500 | S23: Unidad 500 g | W23: =IF(V23="","",IFERROR(V23/O23,"")) | Z23: 3 | AA23: SR4 | AB23: =IFERROR(INDEX(TABLA_IVA!$C$3:$C$6,MATCH(AA23,TABLA_IVA!$A$3:$A$6,0)),"") -> 0.04 | AC23: 0.52 | AD23: FIJO | AE23: 0.75 | AF23: =IF(OR(AC23="",AE23="",AB23=""),"",IFERROR(AC23/(1-AE23)*(1+AB23),"")) -> 2.1632 | AG23: 2.4 | AH23: =IF(AD23="FIJO",IF(AG23="","",AG23),IF(AF23<>"",AF23,IF(AG23="","",AG23))) -> 2.4 | AI23: =IF(OR(AH23="",AB23=""),"",IFERROR(AH23/(1+AB23),"")) -> 2.3076923 | AJ23: =IF(OR(AI23="",AC23=""),"",IFERROR((AI23-AC23)/AI23,"")) -> 0.77466667 | AK23: =IF(OR(AJ23="",AE23=""),"",AJ23-AE23) -> 0.024666667 | AL23: =IF(OR(AH23="",AF23=""),"",AH23-AF23) -> 0.2368 | AM23: =IF(OR(A23="",K23<>"SI"),"",IF(AE23="","Sin objetivo",IF(AJ23="","Faltan datos",IF(AJ23<0,"PÉRDIDA",IF(AK23<-UMB_CRITICO,"MUY POR DEBAJO",IF(AK23<-UMB_BAJO,"POR DEBAJO",IF(AK23<-UMB_AJUSTADO,"AJUSTADO",IF(AK23<=UMB_ALTO,"EN OBJETIVO","POR ENCIMA")))))))) -> EN OBJETIVO | AN23: SI | AO23: FIFO | AP23: 0 | AQ23: 0 | AR23: 0 | AS23: Tienda / vitrina | AT23: A | AU23: SI | AV23: 2 | AW23: Ambiente | AX23: Gluten | AY23: Activo | AZ23: 46248
A24: PT-PAN-003 | B24: 8400000000032 | C24: Chapata 200 g | D24: Chapata de aceite de oliva, 200 g | E24: PT | F24: Pan | G24: Chapata | H24: Panadería | I24: NO | J24: SI | K24: SI | L24: SI | M24: ud | P24: ud | Q24: 1 | R24: 200 | S24: Unidad 200 g | W24: =IF(V24="","",IFERROR(V24/O24,"")) | Z24: 3 | AA24: SR4 | AB24: =IFERROR(INDEX(TABLA_IVA!$C$3:$C$6,MATCH(AA24,TABLA_IVA!$A$3:$A$6,0)),"") -> 0.04 | AC24: 0.24 | AD24: FIJO | AE24: 0.75 | AF24: =IF(OR(AC24="",AE24="",AB24=""),"",IFERROR(AC24/(1-AE24)*(1+AB24),"")) -> 0.9984 | AG24: 1.1 | AH24: =IF(AD24="FIJO",IF(AG24="","",AG24),IF(AF24<>"",AF24,IF(AG24="","",AG24))) -> 1.1 | AI24: =IF(OR(AH24="",AB24=""),"",IFERROR(AH24/(1+AB24),"")) -> 1.0576923 | AJ24: =IF(OR(AI24="",AC24=""),"",IFERROR((AI24-AC24)/AI24,"")) -> 0.77309091 | AK24: =IF(OR(AJ24="",AE24=""),"",AJ24-AE24) -> 0.023090909 | AL24: =IF(OR(AH24="",AF24=""),"",AH24-AF24) -> 0.1016 | AM24: =IF(OR(A24="",K24<>"SI"),"",IF(AE24="","Sin objetivo",IF(AJ24="","Faltan datos",IF(AJ24<0,"PÉRDIDA",IF(AK24<-UMB_CRITICO,"MUY POR DEBAJO",IF(AK24<-UMB_BAJO,"POR DEBAJO",IF(AK24<-UMB_AJUSTADO,"AJUSTADO",IF(AK24<=UMB_ALTO,"EN OBJETIVO","POR ENCIMA")))))))) -> EN OBJETIVO | AN24: SI | AO24: FIFO | AP24: 0 | AQ24: 0 | AR24: 0 | AS24: Tienda / vitrina | AT24: B | AU24: SI | AV24: 1 | AW24: Ambiente | AX24: Gluten | AY24: Activo | AZ24: 46248
A25: PT-PAN-004 | B25: 8400000000049 | C25: Pan de molde 750 g | D25: Pan de molde blanco rebanado, 750 g | E25: PT | F25: Pan | G25: Pan de molde | H25: Panadería | I25: NO | J25: SI | K25: SI | L25: SI | M25: ud | P25: ud | Q25: 1 | R25: 750 | S25: Unidad 750 g | W25: =IF(V25="","",IFERROR(V25/O25,"")) | Z25: 4 | AA25: SR4 | AB25: =IFERROR(INDEX(TABLA_IVA!$C$3:$C$6,MATCH(AA25,TABLA_IVA!$A$3:$A$6,0)),"") -> 0.04 | AC25: 0.95 | AD25: FIJO | AE25: 0.75 | AF25: =IF(OR(AC25="",AE25="",AB25=""),"",IFERROR(AC25/(1-AE25)*(1+AB25),"")) -> 3.952 | AG25: 3.2 | AH25: =IF(AD25="FIJO",IF(AG25="","",AG25),IF(AF25<>"",AF25,IF(AG25="","",AG25))) -> 3.2 | AI25: =IF(OR(AH25="",AB25=""),"",IFERROR(AH25/(1+AB25),"")) -> 3.0769231 | AJ25: =IF(OR(AI25="",AC25=""),"",IFERROR((AI25-AC25)/AI25,"")) -> 0.69125 | AK25: =IF(OR(AJ25="",AE25=""),"",AJ25-AE25) -> -0.05875 | AL25: =IF(OR(AH25="",AF25=""),"",AH25-AF25) -> -0.752 | AM25: =IF(OR(A25="",K25<>"SI"),"",IF(AE25="","Sin objetivo",IF(AJ25="","Faltan datos",IF(AJ25<0,"PÉRDIDA",IF(AK25<-UMB_CRITICO,"MUY POR DEBAJO",IF(AK25<-UMB_BAJO,"POR DEBAJO",IF(AK25<-UMB_AJUSTADO,"AJUSTADO",IF(AK25<=UMB_ALTO,"EN OBJETIVO","POR ENCIMA")))))))) -> POR DEBAJO | AN25: SI | AO25: FIFO | AP25: 0 | AQ25: 0 | AR25: 0 | AS25: Tienda / vitrina | AT25: B | AU25: SI | AV25: 5 | AW25: Ambiente | AX25: Gluten;Leche;Soja | AY25: Activo | AZ25: 46248 | BA25: IVA 4% tras Resolución BOE 27/02/2025
A26: PT-BOL-001 | B26: 8400000000056 | C26: Croissant mantequilla | D26: Croissant de mantequilla artesano | E26: PT | F26: Bollería | G26: Croissantería | H26: Pastelería/Obrador | I26: NO | J26: SI | K26: SI | L26: SI | M26: ud | P26: ud | Q26: 1 | R26: 70 | S26: Unidad 70 g | W26: =IF(V26="","",IFERROR(V26/O26,"")) | Z26: 4 | AA26: RD10 | AB26: =IFERROR(INDEX(TABLA_IVA!$C$3:$C$6,MATCH(AA26,TABLA_IVA!$A$3:$A$6,0)),"") -> 0.1 | AC26: 0.42 | AD26: FIJO | AE26: 0.72 | AF26: =IF(OR(AC26="",AE26="",AB26=""),"",IFERROR(AC26/(1-AE26)*(1+AB26),"")) -> 1.65 | AG26: 1.6 | AH26: =IF(AD26="FIJO",IF(AG26="","",AG26),IF(AF26<>"",AF26,IF(AG26="","",AG26))) -> 1.6 | AI26: =IF(OR(AH26="",AB26=""),"",IFERROR(AH26/(1+AB26),"")) -> 1.4545455 | AJ26: =IF(OR(AI26="",AC26=""),"",IFERROR((AI26-AC26)/AI26,"")) -> 0.71125 | AK26: =IF(OR(AJ26="",AE26=""),"",AJ26-AE26) -> -0.00875 | AL26: =IF(OR(AH26="",AF26=""),"",AH26-AF26) -> -0.05 | AM26: =IF(OR(A26="",K26<>"SI"),"",IF(AE26="","Sin objetivo",IF(AJ26="","Faltan datos",IF(AJ26<0,"PÉRDIDA",IF(AK26<-UMB_CRITICO,"MUY POR DEBAJO",IF(AK26<-UMB_BAJO,"POR DEBAJO",IF(AK26<-UMB_AJUSTADO,"AJUSTADO",IF(AK26<=UMB_ALTO,"EN OBJETIVO","POR ENCIMA")))))))) -> EN OBJETIVO | AN26: SI | AO26: FIFO | AP26: 0 | AQ26: 0 | AR26: 0 | AS26: Tienda / vitrina | AT26: A | AU26: SI | AV26: 1 | AW26: Ambiente | AX26: Gluten;Leche;Huevos | AY26: Activo | AZ26: 46248
A27: PT-BOL-002 | B27: 8400000000063 | C27: Napolitana chocolate | D27: Napolitana de hojaldre rellena de chocolate | E27: PT | F27: Bollería | G27: Croissantería | H27: Pastelería/Obrador | I27: NO | J27: SI | K27: SI | L27: SI | M27: ud | P27: ud | Q27: 1 | R27: 90 | S27: Unidad 90 g | W27: =IF(V27="","",IFERROR(V27/O27,"")) | Z27: 4 | AA27: RD10 | AB27: =IFERROR(INDEX(TABLA_IVA!$C$3:$C$6,MATCH(AA27,TABLA_IVA!$A$3:$A$6,0)),"") -> 0.1 | AC27: 0.48 | AD27: FIJO | AE27: 0.72 | AF27: =IF(OR(AC27="",AE27="",AB27=""),"",IFERROR(AC27/(1-AE27)*(1+AB27),"")) -> 1.8857143 | AG27: 1.7 | AH27: =IF(AD27="FIJO",IF(AG27="","",AG27),IF(AF27<>"",AF27,IF(AG27="","",AG27))) -> 1.7 | AI27: =IF(OR(AH27="",AB27=""),"",IFERROR(AH27/(1+AB27),"")) -> 1.5454545 | AJ27: =IF(OR(AI27="",AC27=""),"",IFERROR((AI27-AC27)/AI27,"")) -> 0.68941176 | AK27: =IF(OR(AJ27="",AE27=""),"",AJ27-AE27) -> -0.030588235 | AL27: =IF(OR(AH27="",AF27=""),"",AH27-AF27) -> -0.18571429 | AM27: =IF(OR(A27="",K27<>"SI"),"",IF(AE27="","Sin objetivo",IF(AJ27="","Faltan datos",IF(AJ27<0,"PÉRDIDA",IF(AK27<-UMB_CRITICO,"MUY POR DEBAJO",IF(AK27<-UMB_BAJO,"POR DEBAJO",IF(AK27<-UMB_AJUSTADO,"AJUSTADO",IF(AK27<=UMB_ALTO,"EN OBJETIVO","POR ENCIMA")))))))) -> AJUSTADO | AN27: SI | AO27: FIFO | AP27: 0 | AQ27: 0 | AR27: 0 | AS27: Tienda / vitrina | AT27: A | AU27: SI | AV27: 1 | AW27: Ambiente | AX27: Gluten;Leche;Huevos;Soja | AY27: Activo | AZ27: 46248
A28: PT-BOL-003 | B28: 8400000000070 | C28: Magdalena artesana | D28: Magdalena artesana de aceite de oliva | E28: PT | F28: Bollería | G28: Magdalenas y muffins | H28: Pastelería/Obrador | I28: NO | J28: SI | K28: SI | L28: SI | M28: ud | P28: ud | Q28: 1 | R28: 60 | S28: Unidad 60 g | W28: =IF(V28="","",IFERROR(V28/O28,"")) | Z28: 3 | AA28: RD10 | AB28: =IFERROR(INDEX(TABLA_IVA!$C$3:$C$6,MATCH(AA28,TABLA_IVA!$A$3:$A$6,0)),"") -> 0.1 | AC28: 0.26 | AD28: FIJO | AE28: 0.72 | AF28: =IF(OR(AC28="",AE28="",AB28=""),"",IFERROR(AC28/(1-AE28)*(1+AB28),"")) -> 1.0214286 | AG28: 0.95 | AH28: =IF(AD28="FIJO",IF(AG28="","",AG28),IF(AF28<>"",AF28,IF(AG28="","",AG28))) -> 0.95 | AI28: =IF(OR(AH28="",AB28=""),"",IFERROR(AH28/(1+AB28),"")) -> 0.86363636 | AJ28: =IF(OR(AI28="",AC28=""),"",IFERROR((AI28-AC28)/AI28,"")) -> 0.69894737 | AK28: =IF(OR(AJ28="",AE28=""),"",AJ28-AE28) -> -0.021052632 | AL28: =IF(OR(AH28="",AF28=""),"",AH28-AF28) -> -0.071428571 | AM28: =IF(OR(A28="",K28<>"SI"),"",IF(AE28="","Sin objetivo",IF(AJ28="","Faltan datos",IF(AJ28<0,"PÉRDIDA",IF(AK28<-UMB_CRITICO,"MUY POR DEBAJO",IF(AK28<-UMB_BAJO,"POR DEBAJO",IF(AK28<-UMB_AJUSTADO,"AJUSTADO",IF(AK28<=UMB_ALTO,"EN OBJETIVO","POR ENCIMA")))))))) -> AJUSTADO | AN28: SI | AO28: FIFO | AP28: 0 | AQ28: 0 | AR28: 0 | AS28: Tienda / vitrina | AT28: B | AU28: SI | AV28: 7 | AW28: Ambiente | AX28: Gluten;Huevos | AY28: Activo | AZ28: 46248
A29: PT-PAS-001 | B29: 8400000000087 | C29: Palmera hojaldre | D29: Palmera de hojaldre grande | E29: PT | F29: Pastelería | G29: Hojaldre | H29: Pastelería/Obrador | I29: NO | J29: SI | K29: SI | L29: SI | M29: ud | P29: ud | Q29: 1 | R29: 110 | S29: Unidad 110 g | W29: =IF(V29="","",IFERROR(V29/O29,"")) | Z29: 4 | AA29: RD10 | AB29: =IFERROR(INDEX(TABLA_IVA!$C$3:$C$6,MATCH(AA29,TABLA_IVA!$A$3:$A$6,0)),"") -> 0.1 | AC29: 0.55 | AD29: FIJO | AE29: 0.7 | AF29: =IF(OR(AC29="",AE29="",AB29=""),"",IFERROR(AC29/(1-AE29)*(1+AB29),"")) -> 2.0166667 | AG29: 1.9 | AH29: =IF(AD29="FIJO",IF(AG29="","",AG29),IF(AF29<>"",AF29,IF(AG29="","",AG29))) -> 1.9 | AI29: =IF(OR(AH29="",AB29=""),"",IFERROR(AH29/(1+AB29),"")) -> 1.7272727 | AJ29: =IF(OR(AI29="",AC29=""),"",IFERROR((AI29-AC29)/AI29,"")) -> 0.68157895 | AK29: =IF(OR(AJ29="",AE29=""),"",AJ29-AE29) -> -0.018421053 | AL29: =IF(OR(AH29="",AF29=""),"",AH29-AF29) -> -0.11666667 | AM29: =IF(OR(A29="",K29<>"SI"),"",IF(AE29="","Sin objetivo",IF(AJ29="","Faltan datos",IF(AJ29<0,"PÉRDIDA",IF(AK29<-UMB_CRITICO,"MUY POR DEBAJO",IF(AK29<-UMB_BAJO,"POR DEBAJO",IF(AK29<-UMB_AJUSTADO,"AJUSTADO",IF(AK29<=UMB_ALTO,"EN OBJETIVO","POR ENCIMA")))))))) -> EN OBJETIVO | AN29: SI | AO29: FIFO | AP29: 0 | AQ29: 0 | AR29: 0 | AS29: Tienda / vitrina | AT29: B | AU29: SI | AV29: 3 | AW29: Ambiente | AX29: Gluten;Leche | AY29: Activo | AZ29: 46248
A30: PT-TAR-001 | C30: Tarta de queso porción | D30: Tarta de queso al horno, porción individual | E30: PT | F30: Tartas | G30: Tarta por porción | H30: Pastelería/Obrador | I30: NO | J30: SI | K30: SI | L30: SI | M30: porción | P30: porción | Q30: 1 | R30: 120 | S30: Porción 120 g | W30: =IF(V30="","",IFERROR(V30/O30,"")) | Z30: 6 | AA30: RD10 | AB30: =IFERROR(INDEX(TABLA_IVA!$C$3:$C$6,MATCH(AA30,TABLA_IVA!$A$3:$A$6,0)),"") -> 0.1 | AC30: 0.85 | AD30: FIJO | AE30: 0.7 | AF30: =IF(OR(AC30="",AE30="",AB30=""),"",IFERROR(AC30/(1-AE30)*(1+AB30),"")) -> 3.1166667 | AG30: 3.2 | AH30: =IF(AD30="FIJO",IF(AG30="","",AG30),IF(AF30<>"",AF30,IF(AG30="","",AG30))) -> 3.2 | AI30: =IF(OR(AH30="",AB30=""),"",IFERROR(AH30/(1+AB30),"")) -> 2.9090909 | AJ30: =IF(OR(AI30="",AC30=""),"",IFERROR((AI30-AC30)/AI30,"")) -> 0.7078125 | AK30: =IF(OR(AJ30="",AE30=""),"",AJ30-AE30) -> 0.0078125 | AL30: =IF(OR(AH30="",AF30=""),"",AH30-AF30) -> 0.083333333 | AM30: =IF(OR(A30="",K30<>"SI"),"",IF(AE30="","Sin objetivo",IF(AJ30="","Faltan datos",IF(AJ30<0,"PÉRDIDA",IF(AK30<-UMB_CRITICO,"MUY POR DEBAJO",IF(AK30<-UMB_BAJO,"POR DEBAJO",IF(AK30<-UMB_AJUSTADO,"AJUSTADO",IF(AK30<=UMB_ALTO,"EN OBJETIVO","POR ENCIMA")))))))) -> EN OBJETIVO | AN30: SI | AO30: FIFO | AP30: 0 | AQ30: 0 | AR30: 0 | AS30: Cámara refrigeración | AT30: A | AU30: SI | AV30: 3 | AW30: Refrigerado (0-4 C) | AX30: Gluten;Leche;Huevos | AY30: Activo | AZ30: 46248
A31: PT-TAR-002 | C31: Tarta Sacher 24 cm | D31: Tarta Sacher entera de 24 cm, 10-12 raciones | E31: PT | F31: Tartas | G31: Tarta entera | H31: Pastelería/Obrador | I31: NO | J31: SI | K31: SI | L31: SI | M31: ud | P31: ud | Q31: 1 | R31: 1400 | S31: Tarta 24 cm | W31: =IF(V31="","",IFERROR(V31/O31,"")) | Z31: 5 | AA31: RD10 | AB31: =IFERROR(INDEX(TABLA_IVA!$C$3:$C$6,MATCH(AA31,TABLA_IVA!$A$3:$A$6,0)),"") -> 0.1 | AC31: 8.9 | AD31: FIJO | AE31: 0.7 | AF31: =IF(OR(AC31="",AE31="",AB31=""),"",IFERROR(AC31/(1-AE31)*(1+AB31),"")) -> 32.633333 | AG31: 32 | AH31: =IF(AD31="FIJO",IF(AG31="","",AG31),IF(AF31<>"",AF31,IF(AG31="","",AG31))) -> 32 | AI31: =IF(OR(AH31="",AB31=""),"",IFERROR(AH31/(1+AB31),"")) -> 29.090909 | AJ31: =IF(OR(AI31="",AC31=""),"",IFERROR((AI31-AC31)/AI31,"")) -> 0.6940625 | AK31: =IF(OR(AJ31="",AE31=""),"",AJ31-AE31) -> -0.0059375 | AL31: =IF(OR(AH31="",AF31=""),"",AH31-AF31) -> -0.63333333 | AM31: =IF(OR(A31="",K31<>"SI"),"",IF(AE31="","Sin objetivo",IF(AJ31="","Faltan datos",IF(AJ31<0,"PÉRDIDA",IF(AK31<-UMB_CRITICO,"MUY POR DEBAJO",IF(AK31<-UMB_BAJO,"POR DEBAJO",IF(AK31<-UMB_AJUSTADO,"AJUSTADO",IF(AK31<=UMB_ALTO,"EN OBJETIVO","POR ENCIMA")))))))) -> EN OBJETIVO | AN31: SI | AO31: FIFO | AP31: 0 | AQ31: 0 | AR31: 0 | AS31: Cámara refrigeración | AT31: A | AU31: SI | AV31: 3 | AW31: Refrigerado (0-4 C) | AX31: Gluten;Leche;Huevos;Frutos de cáscara | AY31: Activo | AZ31: 46248 | BA31: Bajo pedido con 24 h
A32: PT-SLD-001 | C32: Empanada atún porción | D32: Empanada de atún casera, porción | E32: PT | F32: Salados | G32: Empanadas | H32: Salados | I32: NO | J32: SI | K32: SI | L32: SI | M32: porción | P32: porción | Q32: 1 | R32: 180 | S32: Porción 180 g | W32: =IF(V32="","",IFERROR(V32/O32,"")) | Z32: 5 | AA32: RD10 | AB32: =IFERROR(INDEX(TABLA_IVA!$C$3:$C$6,MATCH(AA32,TABLA_IVA!$A$3:$A$6,0)),"") -> 0.1 | AC32: 0.9 | AD32: FIJO | AE32: 0.65 | AF32: =IF(OR(AC32="",AE32="",AB32=""),"",IFERROR(AC32/(1-AE32)*(1+AB32),"")) -> 2.8285714 | AG32: 3.1 | AH32: =IF(AD32="FIJO",IF(AG32="","",AG32),IF(AF32<>"",AF32,IF(AG32="","",AG32))) -> 3.1 | AI32: =IF(OR(AH32="",AB32=""),"",IFERROR(AH32/(1+AB32),"")) -> 2.8181818 | AJ32: =IF(OR(AI32="",AC32=""),"",IFERROR((AI32-AC32)/AI32,"")) -> 0.68064516 | AK32: =IF(OR(AJ32="",AE32=""),"",AJ32-AE32) -> 0.030645161 | AL32: =IF(OR(AH32="",AF32=""),"",AH32-AF32) -> 0.27142857 | AM32: =IF(OR(A32="",K32<>"SI"),"",IF(AE32="","Sin objetivo",IF(AJ32="","Faltan datos",IF(AJ32<0,"PÉRDIDA",IF(AK32<-UMB_CRITICO,"MUY POR DEBAJO",IF(AK32<-UMB_BAJO,"POR DEBAJO",IF(AK32<-UMB_AJUSTADO,"AJUSTADO",IF(AK32<=UMB_ALTO,"EN OBJETIVO","POR ENCIMA")))))))) -> EN OBJETIVO | AN32: SI | AO32: FIFO | AP32: 0 | AQ32: 0 | AR32: 0 | AS32: Tienda / vitrina | AT32: B | AU32: SI | AV32: 2 | AW32: Refrigerado (0-4 C) | AX32: Gluten;Pescado;Huevos | AY32: Activo | AZ32: 46248
A33: RV-CAF-001 | C33: Café en grano natural | D33: Café en grano natural para cafetería, 1 kg | E33: RV | F33: Cafetería | G33: Café | H33: Cafetería | I33: SI | J33: NO | K33: SI | L33: NO | M33: kg | N33: caja | O33: 6 | P33: kg | Q33: 1 | S33: Caja 6 x 1 kg | T33: PRV-002 | U33: CAF-NAT | V33: 78 | W33: =IF(V33="","",IFERROR(V33/O33,"")) -> 13 | X33: 7 | Y33: 1 | Z33: 0 | AA33: RD10 | AB33: =IFERROR(INDEX(TABLA_IVA!$C$3:$C$6,MATCH(AA33,TABLA_IVA!$A$3:$A$6,0)),"") -> 0.1 | AC33: 13 | AD33: MARGEN | AE33: 0.3 | AF33: =IF(OR(AC33="",AE33="",AB33=""),"",IFERROR(AC33/(1-AE33)*(1+AB33),"")) -> 20.428571 | AH33: =IF(AD33="FIJO",IF(AG33="","",AG33),IF(AF33<>"",AF33,IF(AG33="","",AG33))) -> 20.428571 | AI33: =IF(OR(AH33="",AB33=""),"",IFERROR(AH33/(1+AB33),"")) -> 18.571429 | AJ33: =IF(OR(AI33="",AC33=""),"",IFERROR((AI33-AC33)/AI33,"")) -> 0.3 | AK33: =IF(OR(AJ33="",AE33=""),"",AJ33-AE33) -> 0 | AL33: =IF(OR(AH33="",AF33=""),"",AH33-AF33) -> 0 | AM33: =IF(OR(A33="",K33<>"SI"),"",IF(AE33="","Sin objetivo",IF(AJ33="","Faltan datos",IF(AJ33<0,"PÉRDIDA",IF(AK33<-UMB_CRITICO,"MUY POR DEBAJO",IF(AK33<-UMB_BAJO,"POR DEBAJO",IF(AK33<-UMB_AJUSTADO,"AJUSTADO",IF(AK33<=UMB_ALTO,"EN OBJETIVO","POR ENCIMA")))))))) -> EN OBJETIVO | AN33: SI | AO33: PMP | AP33: 3 | AQ33: 18 | AR33: 6 | AS33: Almacén seco | AT33: B | AU33: NO | AV33: 365 | AW33: Seco y ventilado | AY33: Activo | AZ33: 46248 | BA33: Se vende como servicio de cafetería: revisar tipo aplicable
A34: RV-BEB-001 | B34: 8400000000094 | C34: Agua mineral 50 cl | D34: Agua mineral natural, botella 50 cl | E34: RV | F34: Bebidas | G34: Agua y zumos | H34: Reventa | I34: SI | J34: NO | K34: SI | L34: NO | M34: ud | N34: caja | O34: 24 | P34: ud | Q34: 1 | S34: Caja 24 x 50 cl | T34: PRV-002 | U34: AGU-50 | V34: 5.76 | W34: =IF(V34="","",IFERROR(V34/O34,"")) -> 0.24 | X34: 7 | Y34: 2 | Z34: 0 | AA34: SR4 | AB34: =IFERROR(INDEX(TABLA_IVA!$C$3:$C$6,MATCH(AA34,TABLA_IVA!$A$3:$A$6,0)),"") -> 0.04 | AC34: 0.24 | AD34: FIJO | AE34: 0.6 | AF34: =IF(OR(AC34="",AE34="",AB34=""),"",IFERROR(AC34/(1-AE34)*(1+AB34),"")) -> 0.624 | AG34: 0.9 | AH34: =IF(AD34="FIJO",IF(AG34="","",AG34),IF(AF34<>"",AF34,IF(AG34="","",AG34))) -> 0.9 | AI34: =IF(OR(AH34="",AB34=""),"",IFERROR(AH34/(1+AB34),"")) -> 0.86538462 | AJ34: =IF(OR(AI34="",AC34=""),"",IFERROR((AI34-AC34)/AI34,"")) -> 0.72266667 | AK34: =IF(OR(AJ34="",AE34=""),"",AJ34-AE34) -> 0.12266667 | AL34: =IF(OR(AH34="",AF34=""),"",AH34-AF34) -> 0.276 | AM34: =IF(OR(A34="",K34<>"SI"),"",IF(AE34="","Sin objetivo",IF(AJ34="","Faltan datos",IF(AJ34<0,"PÉRDIDA",IF(AK34<-UMB_CRITICO,"MUY POR DEBAJO",IF(AK34<-UMB_BAJO,"POR DEBAJO",IF(AK34<-UMB_AJUSTADO,"AJUSTADO",IF(AK34<=UMB_ALTO,"EN OBJETIVO","POR ENCIMA")))))))) -> POR ENCIMA | AN34: SI | AO34: PMP | AP34: 48 | AQ34: 240 | AR34: 96 | AS34: Trastienda | AT34: C | AU34: NO | AV34: 365 | AW34: Ambiente | AY34: Activo | AZ34: 46248
A35: RV-BEB-002 | B35: 8400000000100 | C35: Refresco cola lata 33 cl | D35: Refresco de cola con azúcar, lata 33 cl | E35: RV | F35: Bebidas | G35: Refrescos | H35: Reventa | I35: SI | J35: NO | K35: SI | L35: NO | M35: ud | N35: caja | O35: 24 | P35: ud | Q35: 1 | S35: Caja 24 x 33 cl | T35: PRV-002 | U35: COL-33 | V35: 14.4 | W35: =IF(V35="","",IFERROR(V35/O35,"")) -> 0.6 | X35: 7 | Y35: 1 | Z35: 0 | AA35: GN21 | AB35: =IFERROR(INDEX(TABLA_IVA!$C$3:$C$6,MATCH(AA35,TABLA_IVA!$A$3:$A$6,0)),"") -> 0.21 | AC35: 0.6 | AD35: FIJO | AE35: 0.6 | AF35: =IF(OR(AC35="",AE35="",AB35=""),"",IFERROR(AC35/(1-AE35)*(1+AB35),"")) -> 1.815 | AG35: 1.6 | AH35: =IF(AD35="FIJO",IF(AG35="","",AG35),IF(AF35<>"",AF35,IF(AG35="","",AG35))) -> 1.6 | AI35: =IF(OR(AH35="",AB35=""),"",IFERROR(AH35/(1+AB35),"")) -> 1.322314 | AJ35: =IF(OR(AI35="",AC35=""),"",IFERROR((AI35-AC35)/AI35,"")) -> 0.54625 | AK35: =IF(OR(AJ35="",AE35=""),"",AJ35-AE35) -> -0.05375 | AL35: =IF(OR(AH35="",AF35=""),"",AH35-AF35) -> -0.215 | AM35: =IF(OR(A35="",K35<>"SI"),"",IF(AE35="","Sin objetivo",IF(AJ35="","Faltan datos",IF(AJ35<0,"PÉRDIDA",IF(AK35<-UMB_CRITICO,"MUY POR DEBAJO",IF(AK35<-UMB_BAJO,"POR DEBAJO",IF(AK35<-UMB_AJUSTADO,"AJUSTADO",IF(AK35<=UMB_ALTO,"EN OBJETIVO","POR ENCIMA")))))))) -> POR DEBAJO | AN35: SI | AO35: PMP | AP35: 24 | AQ35: 120 | AR35: 48 | AS35: Trastienda | AT35: C | AU35: NO | AV35: 270 | AW35: Ambiente | AY35: Activo | AZ35: 46248 | BA35: Refrescos azucarados al 21%
W36: =IF(V36="","",IFERROR(V36/O36,"")) | AB36: =IFERROR(INDEX(TABLA_IVA!$C$3:$C$6,MATCH(AA36,TABLA_IVA!$A$3:$A$6,0)),"") | AF36: =IF(OR(AC36="",AE36="",AB36=""),"",IFERROR(AC36/(1-AE36)*(1+AB36),"")) | AH36: =IF(AD36="FIJO",IF(AG36="","",AG36),IF(AF36<>"",AF36,IF(AG36="","",AG36))) | AI36: =IF(OR(AH36="",AB36=""),"",IFERROR(AH36/(1+AB36),"")) | AJ36: =IF(OR(AI36="",AC36=""),"",IFERROR((AI36-AC36)/AI36,"")) | AK36: =IF(OR(AJ36="",AE36=""),"",AJ36-AE36) | AL36: =IF(OR(AH36="",AF36=""),"",AH36-AF36) | AM36: =IF(OR(A36="",K36<>"SI"),"",IF(AE36="","Sin objetivo",IF(AJ36="","Faltan datos",IF(AJ36<0,"PÉRDIDA",IF(AK36<-UMB_CRITICO,"MUY POR DEBAJO",IF(AK36<-UMB_BAJO,"POR DEBAJO",IF(AK36<-UMB_AJUSTADO,"AJUSTADO",IF(AK36<=UMB_ALTO,"EN OBJETIVO","POR ENCIMA"))))))))
W37: =IF(V37="","",IFERROR(V37/O37,"")) | AB37: =IFERROR(INDEX(TABLA_IVA!$C$3:$C$6,MATCH(AA37,TABLA_IVA!$A$3:$A$6,0)),"") | AF37: =IF(OR(AC37="",AE37="",AB37=""),"",IFERROR(AC37/(1-AE37)*(1+AB37),"")) | AH37: =IF(AD37="FIJO",IF(AG37="","",AG37),IF(AF37<>"",AF37,IF(AG37="","",AG37))) | AI37: =IF(OR(AH37="",AB37=""),"",IFERROR(AH37/(1+AB37),"")) | AJ37: =IF(OR(AI37="",AC37=""),"",IFERROR((AI37-AC37)/AI37,"")) | AK37: =IF(OR(AJ37="",AE37=""),"",AJ37-AE37) | AL37: =IF(OR(AH37="",AF37=""),"",AH37-AF37) | AM37: =IF(OR(A37="",K37<>"SI"),"",IF(AE37="","Sin objetivo",IF(AJ37="","Faltan datos",IF(AJ37<0,"PÉRDIDA",IF(AK37<-UMB_CRITICO,"MUY POR DEBAJO",IF(AK37<-UMB_BAJO,"POR DEBAJO",IF(AK37<-UMB_AJUSTADO,"AJUSTADO",IF(AK37<=UMB_ALTO,"EN OBJETIVO","POR ENCIMA"))))))))
W38: =IF(V38="","",IFERROR(V38/O38,"")) | AB38: =IFERROR(INDEX(TABLA_IVA!$C$3:$C$6,MATCH(AA38,TABLA_IVA!$A$3:$A$6,0)),"") | AF38: =IF(OR(AC38="",AE38="",AB38=""),"",IFERROR(AC38/(1-AE38)*(1+AB38),"")) | AH38: =IF(AD38="FIJO",IF(AG38="","",AG38),IF(AF38<>"",AF38,IF(AG38="","",AG38))) | AI38: =IF(OR(AH38="",AB38=""),"",IFERROR(AH38/(1+AB38),"")) | AJ38: =IF(OR(AI38="",AC38=""),"",IFERROR((AI38-AC38)/AI38,"")) | AK38: =IF(OR(AJ38="",AE38=""),"",AJ38-AE38) | AL38: =IF(OR(AH38="",AF38=""),"",AH38-AF38) | AM38: =IF(OR(A38="",K38<>"SI"),"",IF(AE38="","Sin objetivo",IF(AJ38="","Faltan datos",IF(AJ38<0,"PÉRDIDA",IF(AK38<-UMB_CRITICO,"MUY POR DEBAJO",IF(AK38<-UMB_BAJO,"POR DEBAJO",IF(AK38<-UMB_AJUSTADO,"AJUSTADO",IF(AK38<=UMB_ALTO,"EN OBJETIVO","POR ENCIMA"))))))))
W39: =IF(V39="","",IFERROR(V39/O39,"")) | AB39: =IFERROR(INDEX(TABLA_IVA!$C$3:$C$6,MATCH(AA39,TABLA_IVA!$A$3:$A$6,0)),"") | AF39: =IF(OR(AC39="",AE39="",AB39=""),"",IFERROR(AC39/(1-AE39)*(1+AB39),"")) | AH39: =IF(AD39="FIJO",IF(AG39="","",AG39),IF(AF39<>"",AF39,IF(AG39="","",AG39))) | AI39: =IF(OR(AH39="",AB39=""),"",IFERROR(AH39/(1+AB39),"")) | AJ39: =IF(OR(AI39="",AC39=""),"",IFERROR((AI39-AC39)/AI39,"")) | AK39: =IF(OR(AJ39="",AE39=""),"",AJ39-AE39) | AL39: =IF(OR(AH39="",AF39=""),"",AH39-AF39) | AM39: =IF(OR(A39="",K39<>"SI"),"",IF(AE39="","Sin objetivo",IF(AJ39="","Faltan datos",IF(AJ39<0,"PÉRDIDA",IF(AK39<-UMB_CRITICO,"MUY POR DEBAJO",IF(AK39<-UMB_BAJO,"POR DEBAJO",IF(AK39<-UMB_AJUSTADO,"AJUSTADO",IF(AK39<=UMB_ALTO,"EN OBJETIVO","POR ENCIMA"))))))))
W40: =IF(V40="","",IFERROR(V40/O40,"")) | AB40: =IFERROR(INDEX(TABLA_IVA!$C$3:$C$6,MATCH(AA40,TABLA_IVA!$A$3:$A$6,0)),"") | AF40: =IF(OR(AC40="",AE40="",AB40=""),"",IFERROR(AC40/(1-AE40)*(1+AB40),"")) | AH40: =IF(AD40="FIJO",IF(AG40="","",AG40),IF(AF40<>"",AF40,IF(AG40="","",AG40))) | AI40: =IF(OR(AH40="",AB40=""),"",IFERROR(AH40/(1+AB40),"")) | AJ40: =IF(OR(AI40="",AC40=""),"",IFERROR((AI40-AC40)/AI40,"")) | AK40: =IF(OR(AJ40="",AE40=""),"",AJ40-AE40) | AL40: =IF(OR(AH40="",AF40=""),"",AH40-AF40) | AM40: =IF(OR(A40="",K40<>"SI"),"",IF(AE40="","Sin objetivo",IF(AJ40="","Faltan datos",IF(AJ40<0,"PÉRDIDA",IF(AK40<-UMB_CRITICO,"MUY POR DEBAJO",IF(AK40<-UMB_BAJO,"POR DEBAJO",IF(AK40<-UMB_AJUSTADO,"AJUSTADO",IF(AK40<=UMB_ALTO,"EN OBJETIVO","POR ENCIMA"))))))))
...

Sheet CATALOGOS
A1: CATÁLOGOS MAESTROS - puedes ampliar cada lista hacia abajo (las validaciones se actualizan si extiendes el rango con nombre)
A2: TIPO_ARTICULO | B2: SECCION | C2: FAMILIA | D2: SUBFAMILIA | E2: UNIDAD_MEDIDA | F2: SI_NO | G2: VALORACION | H2: METODO_PRECIO | I2: CLASE_ABC | J2: UBICACION | K2: CONSERVACION | L2: ESTADO | M2: ALERGENOS (Regl. UE 1169/2011)
A3: MP | B3: Panadería | C3: Harinas y sémolas | D3: Trigo | E3: kg | F3: SI | G3: PMP | H3: MARGEN | I3: A | J3: Almacén seco | K3: Ambiente | L3: Activo | M3: Gluten
A4: IN | B4: Pastelería/Obrador | C4: Levaduras y mejorantes | D4: Integral / especiales | E4: g | F4: NO | G4: FIFO | H4: FIJO | I4: B | J4: Cámara refrigeración | K4: Refrigerado (0-4 C) | L4: Inactivo | M4: Crustáceos
A5: SE | B5: Salados | C5: Azúcares y edulcorantes | D5: Sin gluten | E5: l | I5: C | J5: Congelador | K5: Congelado (-18 C) | L5: Descatalogado | M5: Huevos
A6: PT | B6: Cafetería | C6: Grasas y aceites | D6: Levadura | E6: ml | J6: Obrador | K6: Seco y ventilado | M6: Pescado
A7: RV | B7: Reventa | C7: Lácteos y huevos | D7: Mejorante | E7: ud | J7: Tienda / vitrina | M7: Cacahuetes
B8: General | C8: Frutas y frutos secos | D8: Azúcar | E8: docena | J8: Trastienda | M8: Soja
C9: Chocolates y coberturas | D9: Mantequilla | E9: bandeja | J9: Sin ubicación | M9: Leche
C10: Aditivos y aromas | D10: Margarina | E10: caja | M10: Frutos de cáscara
C11: Sal y especias | D11: Aceite | E11: saco | M11: Apio
C12: Envases y embalajes | D12: Leche | E12: bote | M12: Mostaza
C13: Consumibles y limpieza | D13: Nata | E13: paquete | M13: Sésamo
C14: Pan | D14: Queso | E14: porción | M14: Sulfitos
C15: Bollería | D15: Huevo | E15: m | M15: Altramuces
C16: Pastelería | D16: Fruta fresca | M16: Moluscos
C17: Tartas | D17: Frutos secos
C18: Salados | D18: Confitura
C19: Bebidas | D19: Cobertura
C20: Cafetería | D20: Cacao
C21: Semielaborados | D21: Colorantes y aromas
D22: Gelificantes
D23: Bolsas y papel
D24: Cajas
D25: Bandejas
D26: Etiquetas
D27: Barra
D28: Hogaza
D29: Chapata
D30: Pan de molde
D31: Pan especial
D32: Croissantería
D33: Magdalenas y muffins
... D49: Otros

Sheet TABLA_IVA
A1: TIPOS DE IVA APLICABLES (España)
A2: COD_IVA | B2: TIPO | C2: PORCENTAJE | D2: APLICACION TIPICA EN PANADERÍA / PASTELERÍA | E2: REFERENCIA (verificar con tu asesor fiscal)
A3: SR4 | B3: Superreducido | C3: 0.04 | D3: Pan de todo tipo (común y especial: molde, colines, tostado, sin gluten, pita), harinas panificables, leche, quesos, huevos, frutas, verduras, legumbres, tubérculos y cereales naturales. | E3: Art. 91.Dos LIVA. La extensión a TODOS los panes deriva de la STS de 24/10/2024 y de la Resolución del Min. de Hacienda publicada en el BOE del 27/02/2025.
A4: RD10 | B4: Reducido | C4: 0.1 | D4: Bollería, pastelería, tartas, galletas, azúcar, aceites, y en general alimentos no incluidos en el 4%. También los servicios de hostelería (consumo en el local). | E4: Art. 91.Uno LIVA.
A5: GN21 | B5: General | C5: 0.21 | D5: Bebidas alcohólicas, bebidas refrescantes con azúcares o edulcorantes añadidos, material de limpieza, envases y embalajes comprados como suministro, artículos no alimentarios. | E5: Art. 90 LIVA.
A6: EX0 | B6: Exento / no sujeto | C6: 0 | D6: Operaciones exentas o partidas sin repercusión de IVA. | E6: Según operación.
A8: AVISO: la clasificación fiscal de cada producto es responsabilidad de la empresa. Los tipos de IVA cambian con frecuencia; confirma con tu asesor fiscal o en la sede electrónica de la AEAT antes de usar estos códigos en facturación. Cuidado con el punto crítico del sector: el mismo producto tributa distinto si se vende para llevar (tipo del alimento) o si se consume en el local (servicio de hostelería, 10%).

Sheet PARAMETROS
A1: PARÁMETROS DE LA POLÍTICA DE PRECIO
A2: Estos umbrales gobiernan el semáforo de la columna DIAGNOSTICO_PRECIO del maestro. Se expresan en PUNTOS PORCENTUALES de desviación entre el margen real y el margen objetivo. Son los valores de arranque sugeridos: ajústalos a la realidad del negocio.
A3: PARÁMETRO | B3: NOMBRE INTERNO | C3: VALOR | D3: SIGNIFICADO
A4: Tolerancia en objetivo | B4: UMB_AJUSTADO | C4: 0.02 | D4: Hasta 2 puntos por debajo del objetivo se considera EN OBJETIVO. Absorbe el redondeo de precios.
A5: Umbral de aviso | B5: UMB_BAJO | C5: 0.05 | D5: Entre 2 y 5 puntos por debajo: AJUSTADO. Vigilar, pero sin urgencia.
A6: Umbral crítico | B6: UMB_CRITICO | C6: 0.15 | D6: Más de 15 puntos por debajo: MUY POR DEBAJO. Exige revisar precio, coste o receta.
A7: Umbral de exceso | B7: UMB_ALTO | C7: 0.05 | D7: Más de 5 puntos por encima: POR ENCIMA. No es un error, pero conviene saber por qué (¿coste desactualizado? ¿precio poco competitivo?).
A9: ESTADOS POSIBLES DEL DIAGNÓSTICO
A10: ESTADO | B10: SIGNIFICADO
A11: Sin objetivo | B11: No se ha fijado MARGEN_OBJETIVO_%. El sistema no puede juzgar el precio.
A12: Faltan datos | B12: Falta el coste o el precio. Hasta completarlos, el margen no es calculable.
A13: PÉRDIDA | B13: El precio de venta está por debajo del coste. Cada unidad vendida destruye caja.
A14: MUY POR DEBAJO | B14: Desviación superior al umbral crítico. Revisar precio, coste o receta.
